Traceback (most recent call last):
  File "/home/yoneyama/base/lib/python3.12/site-packages/jupyter_cache/executors/utils.py", line 58, in single_nb_execution
    executenb(
  File "/home/yoneyama/base/lib/python3.12/site-packages/nbclient/client.py", line 1314, in execute
    return NotebookClient(nb=nb, resources=resources, km=km, **kwargs).execute()
           ^^^^^^^^^^^^^^^^^^^^^^^^^^^^^^^^^^^^^^^^^^^^^^^^^^^^^^^^^^^^^^^^^^^^^
  File "/home/yoneyama/base/lib/python3.12/site-packages/jupyter_core/utils/__init__.py", line 165, in wrapped
    return loop.run_until_complete(inner)
           ^^^^^^^^^^^^^^^^^^^^^^^^^^^^^^
  File "/usr/lib/python3.12/asyncio/base_events.py", line 687, in run_until_complete
    return future.result()
           ^^^^^^^^^^^^^^^
  File "/home/yoneyama/base/lib/python3.12/site-packages/nbclient/client.py", line 709, in async_execute
    await self.async_execute_cell(
  File "/home/yoneyama/base/lib/python3.12/site-packages/nbclient/client.py", line 1062, in async_execute_cell
    await self._check_raise_for_error(cell, cell_index, exec_reply)
  File "/home/yoneyama/base/lib/python3.12/site-packages/nbclient/client.py", line 918, in _check_raise_for_error
    raise CellExecutionError.from_cell_and_msg(cell, exec_reply_content)
nbclient.exceptions.CellExecutionError: An error occurred while executing the following cell:
------------------
import MeCab

mecab = MeCab.Tagger()
with open("neko.txt", "r") as f1, open("neko.txt.mecab", "w+") as f2:
    lines = f1.readlines()
    for text in lines:
        result = mecab.parse(text)
        f2.write(result)
------------------


[0;31m---------------------------------------------------------------------------[0m
[0;31mRuntimeError[0m                              Traceback (most recent call last)
File [0;32m~/base/lib/python3.12/site-packages/MeCab/__init__.py:137[0m, in [0;36mTagger.__init__[0;34m(self, rawargs)[0m
[1;32m    136[0m [38;5;28;01mtry[39;00m:
[0;32m--> 137[0m     [38;5;28;43msuper[39;49m[43m([49m[43mTagger[49m[43m,[49m[43m [49m[38;5;28;43mself[39;49m[43m)[49m[38;5;241;43m.[39;49m[38;5;21;43m__init__[39;49m[43m([49m[43margs[49m[43m)[49m
[1;32m    138[0m [38;5;28;01mexcept[39;00m [38;5;167;01mRuntimeError[39;00m [38;5;28;01mas[39;00m ee:

[0;31mRuntimeError[0m: 

The above exception was the direct cause of the following exception:

[0;31mRuntimeError[0m                              Traceback (most recent call last)
Cell [0;32mIn[1], line 3[0m
[1;32m      1[0m [38;5;28;01mimport[39;00m [38;5;21;01mMeCab[39;00m
[0;32m----> 3[0m mecab [38;5;241m=[39m [43mMeCab[49m[38;5;241;43m.[39;49m[43mTagger[49m[43m([49m[43m)[49m
[1;32m      4[0m [38;5;28;01mwith[39;00m [38;5;28mopen[39m([38;5;124m"[39m[38;5;124mneko.txt[39m[38;5;124m"[39m, [38;5;124m"[39m[38;5;124mr[39m[38;5;124m"[39m) [38;5;28;01mas[39;00m f1, [38;5;28mopen[39m([38;5;124m"[39m[38;5;124mneko.txt.mecab[39m[38;5;124m"[39m, [38;5;124m"[39m[38;5;124mw+[39m[38;5;124m"[39m) [38;5;28;01mas[39;00m f2:
[1;32m      5[0m     lines [38;5;241m=[39m f1[38;5;241m.[39mreadlines()

File [0;32m~/base/lib/python3.12/site-packages/MeCab/__init__.py:139[0m, in [0;36mTagger.__init__[0;34m(self, rawargs)[0m
[1;32m    137[0m     [38;5;28msuper[39m(Tagger, [38;5;28mself[39m)[38;5;241m.[39m[38;5;21m__init__[39m(args)
[1;32m    138[0m [38;5;28;01mexcept[39;00m [38;5;167;01mRuntimeError[39;00m [38;5;28;01mas[39;00m ee:
[0;32m--> 139[0m     [38;5;28;01mraise[39;00m [38;5;167;01mRuntimeError[39;00m(error_info(rawargs)) [38;5;28;01mfrom[39;00m [38;5;21;01mee[39;00m

[0;31mRuntimeError[0m: 
----------------------------------------------------------

Failed initializing MeCab. Please see the README for possible solutions:

    https://github.com/SamuraiT/mecab-python3#common-issues

If you are still having trouble, please file an issue here, and include the
ERROR DETAILS below:

    https://github.com/SamuraiT/mecab-python3/issues

issueを英語で書く必要はありません。

------------------- ERROR DETAILS ------------------------
arguments: 
default dictionary path: /home/yoneyama/base/lib/python3.12/site-packages/unidic/dicdir
[ifs] no such file or directory: /home/yoneyama/base/lib/python3.12/site-packages/unidic/dicdir/mecabrc
----------------------------------------------------------


